Workbook
Name Slicer_doctor_id: #N/A
Name Slicer_Months__appointment_date: #N/A
Name Slicer_reason_for_visit: #N/A
Name Slicer_status: #N/A

Sheet RAW DATA
A1: appointment_id | B1: patient_id | C1: doctor_id | D1: appointment_date | E1: appointment_time | F1: reason_for_visit | G1: status | I1: patient_id | J1: first_name | K1: last_name | L1: gender | M1: date_of_birth | N1: contact_number | O1: address | P1: registration_date | Q1: insurance_provider | R1: insurance_number | S1: email
A2: A001 | B2: P034 | C2: D009 | D2: 45147 | E2: 0.63541667 | F2: Therapy | G2: Scheduled | I2: P001 | J2: David | K2: Williams | L2: F | M2: 20244 | N2: 6939585183 | O2: 789 Pine Rd | P2: 44735 | Q2: WellnessCorp | R2: INS840674 | S2: david.williams@mail.com
A3: A002 | B3: P032 | C3: D004 | D3: 45086 | E3: 0.60416667 | F3: Therapy | G3: No-show | I3: P002 | J3: Emily | K3: Smith | L3: F | M3: 30967 | N3: 8228188767 | O3: 321 Maple Dr | P3: 44576 | Q3: PulseSecure | R3: INS354079 | S3: emily.smith@mail.com
A4: A003 | B4: P048 | C4: D004 | D4: 45105 | E4: 0.33333333 | F4: Consultation | G4: Cancelled | I4: P003 | J4: Laura | K4: Jones | L4: M | M4: 28358 | N4: 8397029847 | O4: 321 Maple Dr | P4: 44599 | Q4: PulseSecure | R4: INS650929 | S4: laura.jones@mail.com
A5: A004 | B5: P025 | C5: D006 | D5: 45170 | E5: 0.38541667 | F5: Consultation | G5: Cancelled | I5: P004 | J5: Michael | K5: Johnson | L5: F | M5: 29637 | N5: 9019443432 | O5: 123 Elm St | P5: 44257 | Q5: HealthIndia | R5: INS789944 | S5: michael.johnson@mail.com
A6: A005 | B6: P040 | C6: D003 | D6: 45113 | E6: 0.53125 | F6: Emergency | G6: No-show | I6: P005 | J6: David | K6: Wilson | L6: M | M6: 22090 | N6: 7734463155 | O6: 123 Elm St | P6: 44468 | Q6: MedCare Plus | R6: INS788105 | S6: david.wilson@mail.com
A7: A006 | B7: P045 | C7: D006 | D7: 45096 | E7: 0.67708333 | F7: Checkup | G7: Scheduled | I7: P006 | J7: Linda | K7: Jones | L7: M | M7: 23178 | N7: 7561777264 | O7: 321 Maple Dr | P7: 44836 | Q7: HealthIndia | R7: INS613758 | S7: linda.jones@mail.com
A8: A007 | B8: P001 | C8: D007 | D8: 45025 | E8: 0.4375 | F8: Consultation | G8: Scheduled | I8: P007 | J8: Alex | K8: Johnson | L8: F | M8: 32667 | N8: 6278710077 | O8: 789 Pine Rd | P8: 44555 | Q8: MedCare Plus | R8: INS465890 | S8: alex.johnson@mail.com
A9: A008 | B9: P016 | C9: D010 | D9: 45070 | E9: 0.36458333 | F9: Consultation | G9: Cancelled | I9: P008 | J9: David | K9: Davis | L9: F | M9: 27946 | N9: 7090558393 | O9: 456 Oak Ave | P9: 44341 | Q9: WellnessCorp | R9: INS545101 | S9: david.davis@mail.com
A10: A009 | B10: P039 | C10: D010 | D10: 44990 | E10: 0.57291667 | F10: Follow-up | G10: Scheduled | I10: P009 | J10: Laura | K10: Davis | L10: M | M10: 26278 | N10: 7060324619 | O10: 321 Maple Dr | P10: 44822 | Q10: PulseSecure | R10: INS136631 | S10: laura.davis@mail.com
A11: A010 | B11: P005 | C11: D003 | D11: 44939 | E11: 0.64583333 | F11: Therapy | G11: Completed | I11: P010 | J11: Michael | K11: Taylor | L11: M | M11: 37177 | N11: 7081396733 | O11: 123 Elm St | P11: 44797 | Q11: WellnessCorp | R11: INS866577 | S11: michael.taylor@mail.com
A12: A011 | B12: P022 | C12: D007 | D12: 45242 | E12: 0.66666667 | F12: Checkup | G12: No-show | I12: P011 | J12: Emily | K12: Jones | L12: F | M12: 24445 | N12: 8990604070 | O12: 789 Pine Rd | P12: 44831 | Q12: MedCare Plus | R12: INS172991 | S12: emily.jones@mail.com
A13: A012 | B13: P029 | C13: D003 | D13: 45053 | E13: 0.41666667 | F13: Follow-up | G13: Completed | I13: P012 | J13: Laura | K13: Davis | L13: F | M13: 33580 | N13: 8135666049 | O13: 321 Maple Dr | P13: 45043 | Q13: MedCare Plus | R13: INS104014 | S13: laura.davis@mail.com
... A51: A050 | B51: P045 | C51: D008 | D51: 45154 | E51: 0.625 | F51: Consultation | G51: No-show | I51: P050 | J51: Laura | K51: Wilson | L51: M | M51: 34330 | N51: 8301134730 | O51: 321 Maple Dr | P51: 45044 | Q51: WellnessCorp | R51: INS712210 | S51: laura.wilson@mail.com
A52: A051 | B52: P004 | C52: D006 | D52: 44961 | E52: 0.48958333 | F52: Checkup | G52: Completed
A53: A052 | B53: P016 | C53: D008 | D53: 45119 | E53: 0.39583333 | F53: Therapy | G53: No-show
A54: A053 | B54: P024 | C54: D005 | D54: 44969 | E54: 0.4375 | F54: Checkup | G54: Cancelled
A55: A054 | B55: P016 | C55: D008 | D55: 45276 | E55: 0.48958333 | F55: Follow-up | G55: Scheduled
A56: A055 | B56: P002 | C56: D010 | D56: 45205 | E56: 0.72916667 | F56: Checkup | G56: Scheduled
A57: A056 | B57: P049 | C57: D004 | D57: 44928 | E57: 0.53125 | F57: Checkup | G57: Scheduled
A58: A057 | B58: P028 | C58: D010 | D58: 45031 | E58: 0.73958333 | F58: Emergency | G58: Completed
A59: A058 | B59: P032 | C59: D008 | D59: 45055 | E59: 0.55208333 | F59: Consultation | G59: No-show
A60: A059 | B60: P027 | C60: D010 | D60: 44994 | E60: 0.64583333 | F60: Therapy | G60: Cancelled
A61: A060 | B61: P020 | C61: D002 | D61: 45252 | E61: 0.71875 | F61: Checkup | G61: No-show
A62: A061 | B62: P024 | C62: D005 | D62: 44941 | E62: 0.70833333 | F62: Therapy | G62: No-show
A63: A062 | B63: P012 | C63: D009 | D63: 45091 | E63: 0.63541667 | F63: Checkup | G63: No-show
... A201: A200 | B201: P007 | C201: D005 | D201: 45290 | E201: 0.42708333 | F201: Consultation | G201: Cancelled

Sheet Sheet1
A3: Row Labels | B3: Count of appointment_id
A4: Cancelled | B4: 38
A5: Completed | B5: 40
A6: No-show | B6: 40
A7: Scheduled | B7: 39
A8: Grand Total | B8: 157

Sheet Sheet2
A3: Row Labels | B3: Count of status
A4: D001 | B4: 25
A5: D002 | B5: 21
A6: D003 | B6: 22
A7: D004 | B7: 14
A8: D005 | B8: 29
A9: D006 | B9: 24
A10: D007 | B10: 13
A11: D008 | B11: 16
A12: D009 | B12: 17
A13: D010 | B13: 19
A14: Grand Total | B14: 200

Sheet CLEANED DATA
A1: appointment_id | B1: patient_id | C1: doctor_id | D1: appointment_date | E1: appointment_time | F1: reason_for_visit | G1: status | H1: first_name | I1: last_name | J1: full_name | K1: gender | L1: date_of_birth | M1: age | N1: contact_number | O1: address | P1: registration_date | Q1: insurance_provider | R1: insurance_number | S1: email | T1: age group
A2: A001 | B2: P034 | C2: D009 | D2: 45147 | E2: 0.63541667 | F2: Therapy | G2: Scheduled | H2: Alex | I2: Smith | J2: =CONCATENATE(H2," ",I2) -> Alex Smith | K2: F | L2: 18289 | M2: 76 | N2: 8374657733 | O2: 321 Maple Dr | P2: 45095 | Q2: WellnessCorp | R2: INS653880 | S2: alex.smith@mail.com | T2: {=_xlfn.IFS(Table1[[#This Row],[age]]<=17,"CHILD",Table1[[#This Row],[age]]<=35,"YOUNG ADULT",Table1[[#This Row],[age]]<=55,"MIDDLE AGE",Table1[[#This Row],[age]]>=56,"SENIOR")} -> SENIOR
A3: A002 | B3: P032 | C3: D004 | D3: 45086 | E3: 0.60416667 | F3: Therapy | G3: No-show | H3: Alex | I3: Moore | J3: =CONCATENATE(H3," ",I3) -> Alex Moore | K3: M | L3: 29594 | M3: 45 | N3: 8102183595 | O3: 123 Elm St | P3: 44471 | Q3: MedCare Plus | R3: INS335362 | S3: alex.moore@mail.com | T3: {=_xlfn.IFS(Table1[[#This Row],[age]]<=17,"CHILD",Table1[[#This Row],[age]]<=35,"YOUNG ADULT",Table1[[#This Row],[age]]<=55,"MIDDLE AGE",Table1[[#This Row],[age]]>=56,"SENIOR")} -> MIDDLE AGE
A4: A003 | B4: P048 | C4: D004 | D4: 45105 | E4: 0.33333333 | F4: Consultation | G4: Cancelled | H4: Emily | I4: Miller | J4: =CONCATENATE(H4," ",I4) -> Emily Miller | K4: M | L4: 30399 | M4: 43 | N4: 8720989381 | O4: 123 Elm St | P4: 45096 | Q4: PulseSecure | R4: INS694319 | S4: emily.miller@mail.com | T4: {=_xlfn.IFS(Table1[[#This Row],[age]]<=17,"CHILD",Table1[[#This Row],[age]]<=35,"YOUNG ADULT",Table1[[#This Row],[age]]<=55,"MIDDLE AGE",Table1[[#This Row],[age]]>=56,"SENIOR")} -> MIDDLE AGE
A5: A004 | B5: P025 | C5: D006 | D5: 45170 | E5: 0.38541667 | F5: Consultation | G5: Cancelled | H5: Robert | I5: Wilson | J5: =CONCATENATE(H5," ",I5) -> Robert Wilson | K5: M | L5: 24333 | M5: 60 | N5: 7482069727 | O5: 123 Elm St | P5: 44448 | Q5: HealthIndia | R5: INS833429 | S5: robert.wilson@mail.com | T5: {=_xlfn.IFS(Table1[[#This Row],[age]]<=17,"CHILD",Table1[[#This Row],[age]]<=35,"YOUNG ADULT",Table1[[#This Row],[age]]<=55,"MIDDLE AGE",Table1[[#This Row],[age]]>=56,"SENIOR")} -> SENIOR
A6: A005 | B6: P040 | C6: D003 | D6: 45113 | E6: 0.53125 | F6: Emergency | G6: No-show | H6: Emily | I6: Williams | J6: =CONCATENATE(H6," ",I6) -> Emily Williams | K6: M | L6: 26449 | M6: 54 | N6: 7587653815 | O6: 456 Oak Ave | P6: 44485 | Q6: PulseSecure | R6: INS320984 | S6: emily.williams@mail.com | T6: {=_xlfn.IFS(Table1[[#This Row],[age]]<=17,"CHILD",Table1[[#This Row],[age]]<=35,"YOUNG ADULT",Table1[[#This Row],[age]]<=55,"MIDDLE AGE",Table1[[#This Row],[age]]>=56,"SENIOR")} -> MIDDLE AGE
A7: A006 | B7: P045 | C7: D006 | D7: 45096 | E7: 0.67708333 | F7: Checkup | G7: Scheduled | H7: Linda | I7: Miller | J7: =CONCATENATE(H7," ",I7) -> Linda Miller | K7: F | L7: 24222 | M7: 60 | N7: 7579616535 | O7: 321 Maple Dr | P7: 44219 | Q7: MedCare Plus | R7: INS701863 | S7: linda.miller@mail.com | T7: {=_xlfn.IFS(Table1[[#This Row],[age]]<=17,"CHILD",Table1[[#This Row],[age]]<=35,"YOUNG ADULT",Table1[[#This Row],[age]]<=55,"MIDDLE AGE",Table1[[#This Row],[age]]>=56,"SENIOR")} -> SENIOR
A8: A007 | B8: P001 | C8: D007 | D8: 45025 | E8: 0.4375 | F8: Consultation | G8: Scheduled | H8: David | I8: Williams | J8: =CONCATENATE(H8," ",I8) -> David Williams | K8: F | L8: 20244 | M8: 71 | N8: 6939585183 | O8: 789 Pine Rd | P8: 44735 | Q8: WellnessCorp | R8: INS840674 | S8: david.williams@mail.com | T8: {=_xlfn.IFS(Table1[[#This Row],[age]]<=17,"CHILD",Table1[[#This Row],[age]]<=35,"YOUNG ADULT",Table1[[#This Row],[age]]<=55,"MIDDLE AGE",Table1[[#This Row],[age]]>=56,"SENIOR")} -> SENIOR
A9: A008 | B9: P016 | C9: D010 | D9: 45070 | E9: 0.36458333 | F9: Consultation | G9: Cancelled | H9: Michael | I9: Taylor | J9: =CONCATENATE(H9," ",I9) -> Michael Taylor | K9: M | L9: 36729 | M9: 26 | N9: 7223380592 | O9: 789 Pine Rd | P9: 44400 | Q9: PulseSecure | R9: INS156958 | S9: michael.taylor@mail.com | T9: {=_xlfn.IFS(Table1[[#This Row],[age]]<=17,"CHILD",Table1[[#This Row],[age]]<=35,"YOUNG ADULT",Table1[[#This Row],[age]]<=55,"MIDDLE AGE",Table1[[#This Row],[age]]>=56,"SENIOR")} -> YOUNG ADULT
A10: A009 | B10: P039 | C10: D010 | D10: 44990 | E10: 0.57291667 | F10: Follow-up | G10: Scheduled | H10: Jane | I10: Wilson | J10: =CONCATENATE(H10," ",I10) -> Jane Wilson | K10: F | L10: 18609 | M10: 75 | N10: 9271131338 | O10: 789 Pine Rd | P10: 44264 | Q10: PulseSecure | R10: INS348710 | S10: jane.wilson@mail.com | T10: {=_xlfn.IFS(Table1[[#This Row],[age]]<=17,"CHILD",Table1[[#This Row],[age]]<=35,"YOUNG ADULT",Table1[[#This Row],[age]]<=55,"MIDDLE AGE",Table1[[#This Row],[age]]>=56,"SENIOR")} -> SENIOR
A11: A010 | B11: P005 | C11: D003 | D11: 44939 | E11: 0.64583333 | F11: Therapy | G11: Completed | H11: David | I11: Wilson | J11: =CONCATENATE(H11," ",I11) -> David Wilson | K11: M | L11: 22090 | M11: 66 | N11: 7734463155 | O11: 123 Elm St | P11: 44468 | Q11: MedCare Plus | R11: INS788105 | S11: david.wilson@mail.com | T11: {=_xlfn.IFS(Table1[[#This Row],[age]]<=17,"CHILD",Table1[[#This Row],[age]]<=35,"YOUNG ADULT",Table1[[#This Row],[age]]<=55,"MIDDLE AGE",Table1[[#This Row],[age]]>=56,"SENIOR")} -> SENIOR
A12: A011 | B12: P022 | C12: D007 | D12: 45242 | E12: 0.66666667 | F12: Checkup | G12: No-show | H12: John | I12: Brown | J12: =CONCATENATE(H12," ",I12) -> John Brown | K12: M | L12: 20219 | M12: 71 | N12: 6221099573 | O12: 321 Maple Dr | P12: 44327 | Q12: MedCare Plus | R12: INS258823 | S12: john.brown@mail.com | T12: {=_xlfn.IFS(Table1[[#This Row],[age]]<=17,"CHILD",Table1[[#This Row],[age]]<=35,"YOUNG ADULT",Table1[[#This Row],[age]]<=55,"MIDDLE AGE",Table1[[#This Row],[age]]>=56,"SENIOR")} -> SENIOR
A13: A012 | B13: P029 | C13: D003 | D13: 45053 | E13: 0.41666667 | F13: Follow-up | G13: Completed | H13: David | I13: Smith | J13: =CONCATENATE(H13," ",I13) -> David Smith | K13: M | L13: 38487 | M13: 21 | N13: 8923607677 | O13: 789 Pine Rd | P13: 45035 | Q13: HealthIndia | R13: INS630089 | S13: david.smith@mail.com | T13: {=_xlfn.IFS(Table1[[#This Row],[age]]<=17,"CHILD",Table1[[#This Row],[age]]<=35,"YOUNG ADULT",Table1[[#This Row],[age]]<=55,"MIDDLE AGE",Table1[[#This Row],[age]]>=56,"SENIOR")} -> YOUNG ADULT
... A201: A200 | B201: P007 | C201: D005 | D201: 45290 | E201: 0.42708333 | F201: Consultation | G201: Cancelled | H201: Alex | I201: Johnson | J201: =CONCATENATE(H201," ",I201) -> Alex Johnson | K201: F | L201: 32667 | M201: 37 | N201: 6278710077 | O201: 789 Pine Rd | P201: 44555 | Q201: MedCare Plus | R201: INS465890 | S201: alex.johnson@mail.com | T201: {=_xlfn.IFS(Table1[[#This Row],[age]]<=17,"CHILD",Table1[[#This Row],[age]]<=35,"YOUNG ADULT",Table1[[#This Row],[age]]<=55,"MIDDLE AGE",Table1[[#This Row],[age]]>=56,"SENIOR")} -> MIDDLE AGE

Sheet 1
A3: Count of appointment_id
A4: 200

Sheet CHANGELOG
A1: CHANGELOG
A2: 1.All blank values were checked. No blanks found.
A3: 2.All missing values were checked. No missing values found.
A4: 3.All duplicate values were checked. No duplicate found.
A5: 4.Date formats were checked and standardized.
A6: 5.Full Name column was added.
A7: 6.Age column was calculated and added.
A8: 7.Age group categories.
A9: 8.Converted into an Excell table.

Sheet CHARTS
A1: CHART

Sheet ANALYSIS
B1: PIVOT TABLES | E1: CALCULATIONS
E2: 1.How many total appointments are there? | K2: =COUNTA(Table1[appointment_id]) -> 200
A3: 1 | B3: Count of appointment_id | E3: 2.How many appointments are completed? | K3: =COUNTIF(Table1[status],"Completed") -> 46
B4: 200 | E4: 3.What is the average patient age? | K4: =AVERAGE('CLEANED DATA'!M162:M201) -> 45.75
E5: 4.What is the maximum patient age? | K5: =MAX(Table1[age])
A6: 2 | B6: Row Labels | C6: Count of appointment_id | E6: 5.what is the total number of appointments by status? | K6: Cancelled | L6: =COUNTIF('CLEANED DATA'!G162:G201,K6) -> 15
B7: Cancelled | C7: 51 | K7: Completed | L7: =COUNTIF('CLEANED DATA'!G163:G202,K7) -> 7
B8: Completed | C8: 46 | K8: No-show | L8: =COUNTIF('CLEANED DATA'!G164:G203,K8) -> 7
B9: No-show | C9: 52 | K9: Scheduled | L9: =COUNTIF('CLEANED DATA'!G162:G201,K9) -> 10
B10: Scheduled | C10: 51 | E10: 6.what is the minimum patient age? | K10: =MIN('CLEANED DATA'!M162:M201) -> 21
B11: Grand Total | C11: 200
A13: 3 | B13: Row Labels | C13: Count of appointment_id
B14: Checkup | C14: 45
B15: Consultation | C15: 43
B16: Emergency | C16: 29
B17: Follow-up | C17: 41
B18: Therapy | C18: 42
B19: Grand Total | C19: 200
A21: 4 | B21: Row Labels | C21: Count of appointment_id
B22: D001 | C22: 25
B23: D002 | C23: 21
B24: D003 | C24: 22
B25: D004 | C25: 14
B26: D005 | C26: 29
B27: D006 | C27: 24
B28: D007 | C28: 13
B29: D008 | C29: 16
B30: D009 | C30: 17
B31: D010 | C31: 19
B32: Grand Total | C32: 200
A34: 5 | B34: Row Labels | C34: Count of appointment_id
B35: Jan | C35: 20
B36: Feb | C36: 14
B37: Mar | C37: 19
B38: Apr | C38: 25
B39: May | C39: 19
B40: Jun | C40: 18
B41: Jul | C41: 16
B42: Aug | C42: 15
B43: Sep | C43: 11
...

Sheet DASHBOARD
A1: DASHBOARD

Sheet 2
A3: Row Labels | B3: Count of appointment_id
A4: Cancelled | B4: 38
A5: Completed | B5: 40
A6: No-show | B6: 40
A7: Scheduled | B7: 39
A8: Grand Total | B8: 157

Sheet 3
A3: Row Labels | B3: Count of appointment_id
A4: Checkup | B4: 34
A5: Consultation | B5: 33
A6: Emergency | B6: 23
A7: Follow-up | B7: 33
A8: Therapy | B8: 34
A9: Grand Total | B9: 157

Sheet 4
A3: Row Labels | B3: Count of appointment_id
A4: D001 | B4: 18
A5: D002 | B5: 13
A6: D003 | B6: 15
A7: D004 | B7: 13
A8: D005 | B8: 22
A9: D006 | B9: 21
A10: D007 | B10: 10
A11: D008 | B11: 14
A12: D009 | B12: 17
A13: D010 | B13: 14
A14: Grand Total | B14: 157

Sheet 5
A3: Row Labels | B3: Count of appointment_id
A4: Jan | B4: 20
A5: Feb | B5: 14
A6: Mar | B6: 19
A7: Apr | B7: 25
A8: May | B8: 19
A9: Jun | B9: 18
A10: Jul | B10: 16
A11: Aug | B11: 15
A12: Sep | B12: 11
A13: Grand Total | B13: 157

Sheet INSIGHTS
C4: DASHBOARD QUESTIONS | J4: EXCELL QUESTIONS
C5: 1.How many total appointments were scheduled? | J5: 1.How many total appointments are there?
C6: 2.What is the appointment status distribution? | J6: 2.How many appointments are completed?
C7: 3.Which reason for visit has the highest number of appointments? | J7: 3.What is the average patient age?
C8: 4.Which doctors have the highest number of appointments? | J8: 4.What is the maximum patient age?
C9: 5.How do appointments vary by month? | J9: 5.what is the total number of appointments by status?
C10: 6.What is the age group distribution of patients? | J10: 6.what is theminimum patient age?
C11: 7.Which insurance company provide highest ?
C15: INSIGHTS AND RECOMMENDATION
C16: 1. Appointment completion is low
C17: Insigts:
C18: Out of 200 appointments, only 46 appointments were completed (23%). At the same time, cancelled and no-show appointments together account for about 51%.
C19: Recommendation:
C20: “The hospital should focus on reducing cancellations and patient no-shows by using appointment reminders, confirmation calls, and easy rescheduling options.”
C21: 2. No-show appointments are a major concern
C22: Insigts:
C23: Approximately 26% of appointments are no-shows, which is higher than the completed appointments percentage.
C24: Recommendation:
C25: Send SMS/WhatsApp reminders.
... C60: 5. Appointments reached a peak of 25 in April but declined afterward, so the hospital should investigate the reason for this decrease.

Sheet 6
A3: Row Labels | B3: Count of appointment_id
A4: MIDDLE AGE | B4: 60
A5: SENIOR | B5: 51
A6: YOUNG ADULT | B6: 89
A7: Grand Total | B7: 200

Sheet 7
A3: Row Labels | B3: Count of patient_id
A4: HealthIndia | B4: 0.11
A5: MedCare Plus | B5: 0.42
A6: PulseSecure | B6: 0.18
A7: WellnessCorp | B7: 0.29
A8: Grand Total | B8: 1
